#VRML_SIM R2023b utf8

EXTERNPROTO "https://raw.githubusercontent.com/cyberbotics/webots/R2023b/projects/objects/backgrounds/protos/TexturedBackground.proto"
EXTERNPROTO "https://raw.githubusercontent.com/cyberbotics/webots/R2023b/projects/objects/backgrounds/protos/TexturedBackgroundLight.proto"
EXTERNPROTO "https://raw.githubusercontent.com/cyberbotics/webots/R2023b/projects/objects/apartment_structure/protos/Wall.proto"
EXTERNPROTO "https://raw.githubusercontent.com/cyberbotics/webots/R2023b/projects/appearances/protos/Roughcast.proto"
EXTERNPROTO "https://raw.githubusercontent.com/cyberbotics/webots/R2023b/projects/objects/trees/protos/Tree.proto"
EXTERNPROTO "https://raw.githubusercontent.com/cyberbotics/webots/R2023b/projects/objects/living_room_furniture/protos/Sofa.proto"
EXTERNPROTO "https://raw.githubusercontent.com/cyberbotics/webots/R2023b/projects/objects/apartment_structure/protos/Door.proto"
EXTERNPROTO "https://raw.githubusercontent.com/cyberbotics/webots/R2023b/projects/objects/bathroom/protos/Toilet.proto"
EXTERNPROTO "https://raw.githubusercontent.com/cyberbotics/webots/R2023b/projects/objects/trees/protos/PalmTree.proto"
EXTERNPROTO "https://raw.githubusercontent.com/cyberbotics/webots/R2023b/projects/vehicles/protos/abstract/GenericTireAppearance.proto"
EXTERNPROTO "https://raw.githubusercontent.com/cyberbotics/webots/R2023b/projects/appearances/protos/Plastic.proto"
EXTERNPROTO "https://raw.githubusercontent.com/cyberbotics/webots/R2023b/projects/objects/bedroom/protos/Bed.proto"
EXTERNPROTO "https://raw.githubusercontent.com/cyberbotics/webots/R2023b/projects/objects/garden/protos/TableWithUmbrella.proto"
EXTERNPROTO "https://raw.githubusercontent.com/cyberbotics/webots/R2023b/projects/objects/floors/protos/Floor.proto"
EXTERNPROTO "https://raw.githubusercontent.com/cyberbotics/webots/R2023b/projects/objects/kitchen/fridge/protos/Fridge.proto"
EXTERNPROTO "https://raw.githubusercontent.com/cyberbotics/webots/R2023b/projects/objects/kitchen/components/protos/Worktop.proto"
EXTERNPROTO "https://raw.githubusercontent.com/cyberbotics/webots/R2023b/projects/objects/kitchen/oven/protos/Oven.proto"
EXTERNPROTO "https://raw.githubusercontent.com/cyberbotics/webots/R2023b/projects/objects/kitchen/components/protos/HotPlate.proto"
EXTERNPROTO "https://raw.githubusercontent.com/cyberbotics/webots/R2023b/projects/objects/kitchen/components/protos/Sink.proto"
EXTERNPROTO "https://raw.githubusercontent.com/cyberbotics/webots/R2023b/projects/objects/cabinet/protos/Cabinet.proto"
EXTERNPROTO "https://raw.githubusercontent.com/cyberbotics/webots/R2023b/projects/objects/lights/protos/FloorLight.proto"
EXTERNPROTO "https://raw.githubusercontent.com/cyberbotics/webots/R2023b/projects/objects/living_room_furniture/protos/Armchair.proto"
EXTERNPROTO "https://raw.githubusercontent.com/cyberbotics/webots/R2023b/projects/objects/bathroom/protos/BathroomSink.proto"
EXTERNPROTO "https://raw.githubusercontent.com/cyberbotics/webots/R2023b/projects/appearances/protos/Parquetry.proto"
EXTERNPROTO "https://raw.githubusercontent.com/cyberbotics/webots/R2023b/projects/objects/garden/protos/PicketFence.proto"

WorldInfo {
}
Viewpoint {
  orientation -0.6219212187787775 0.4622243024571596 0.6321097150421852 2.2632085410321237
  position -8.123217378597333 -0.43572716186950466 8.461933770762274
}
Floor {
  tileSize 2 2
}
BathroomSink {
  translation 1.44 -4.97 1.06
  rotation 0 0 1 1.5707996938995747
  name "sink(1)"
}
Armchair {
  translation 0 -3.15 0
  rotation 0 0 1 3.141592653589793
}
FloorLight {
  translation -4.49 4.5 0
}
Cabinet {
  hidden position_6_0 3.200533180347641e-05
  hidden translation_7 -6.36906102780445e-06 -1.0192216515214625e-10 0
  hidden rotation_7 0 0 1 3.200533550101502e-05
  hidden position_10_0 -2.7209347397403504e-05
  hidden translation_11 -4.602461111702901e-06 6.261488549874628e-11 0
  hidden rotation_11 0 0 -1 2.7209340807520788e-05
  hidden translation_15 0 0 0
  hidden translation_23 0 0 0
  hidden translation_31 0 0 0
  hidden translation_39 0 0 0
  translation 1.16 4.22 0
  rotation 0 0 1 -3.141592653589793
}
Sink {
  translation 4.51 4.57 0.85
  rotation 0 0 1 -1.5707996938995747
}
Worktop {
  translation 3.13 4.57 0.76
  size 3.8 0.63 0.06
}
Worktop {
  translation 3.55 4.2949 0.274645
  rotation 1 0 0 1.3089996938995747
  name "worktop(1)"
  size 2.8 0.63 0.06
}
HotPlate {
  translation 3.27 4.56 0.79
}
Oven {
  hidden translation_1 0.25 0 0.19
  translation 1.73 4.37 0
  rotation 0 0 1 -1.5707996938995747
}
Fridge {
  hidden position_0_0 -0.00021957073462589735
  hidden position_0_1 0.00021957081272551638
  hidden translation_1 0.36 0.34 1.55
  hidden rotation_1 0 0 -1 0.00021957073548917432
  hidden translation_2 0.36 0.34 0.65
  hidden rotation_2 0 0 1 0.00021957081234544123
  translation 1.69 1.56 0
}
TexturedBackground {
  texture "dusk"
}
TexturedBackgroundLight {
}
DEF WheelChair Robot {
  translation -7.941 -0.16689 0.07
  rotation 0 0 1 -3.141592653589793
  children [
    InertialUnit {
      translation 0 0 0.09
      rotation 0 0 1 -1.5708003061004252
      name "imu"
    }
    DEF sensor_holder Solid {
      translation 0 0 0.1
      children [
        GPS {
          translation 0 0 0.07
          children [
            Shape {
              geometry Cone {
                bottomRadius 0.02
                height 0.05
              }
            }
          ]
        }
        DistanceSensor {
          translation 0.25 0 -0.08
          children [
            Shape {
              appearance PBRAppearance {
              }
              geometry Box {
                size 0.02 0.02 0.02
              }
            }
          ]
          name "ps1"
          lookupTable [
            0 0 0
            5 5 0
            10 10 0
            15 15 0
            20 20 0
          ]
          aperture 1.5705
          gaussianWidth 100
        }
        DistanceSensor {
          translation -0.26 0.000175278 0.01
          rotation 0 0 1 3.14
          children [
            Shape {
              appearance PBRAppearance {
              }
              geometry Box {
                size 0.02 0.02 0.02
              }
            }
          ]
          name "ps2"
          lookupTable [
            0 0 0
            5 5 0
            10 10 0
            15 15 0
            20 20 0
          ]
        }
        DistanceSensor {
          translation 7.96329e-05 0.25 0.49
          rotation 0 0 1 1.57
          children [
            Shape {
              appearance PBRAppearance {
              }
              geometry Box {
                size 0.02 0.02 0.02
              }
            }
          ]
          name "ps3"
          lookupTable [
            0 0 0
            5 5 0
            10 10 0
            15 15 0
            20 20 0
          ]
        }
        DistanceSensor {
          translation 0.00338703 -0.259945 0.5
          rotation 0 0 1 -1.54
          children [
            Shape {
              appearance PBRAppearance {
              }
              geometry Box {
                size 0.02 0.02 0.02
              }
            }
          ]
          name "ps4"
          lookupTable [
            0 0 0
            5 5 0
            10 10 0
            15 15 0
            20 20 0
          ]
        }
        DistanceSensor {
          translation 0.0666623 -0.135693 0
          rotation 0 0 -1 1.0164
          children [
            Shape {
              appearance PBRAppearance {
              }
              geometry Box {
                size 0.02 0.02 0.02
              }
            }
          ]
          name "ps5"
        }
        DistanceSensor {
          translation 0.162626 -0.23211 0.5
          rotation 0 0 1 -0.25
          children [
            Shape {
              appearance PBRAppearance {
              }
              geometry Box {
                size 0.02 0.02 0.02
              }
            }
          ]
          name "ps6"
          lookupTable [
            0 0 0
            5 5 0
            10 10 0
            15 15 0
            20 20 0
          ]
        }
        DistanceSensor {
          translation -0.0759853 -0.135801 0
          rotation 0 0 1 -2.1251953071795864
          children [
            Shape {
              appearance PBRAppearance {
              }
              geometry Box {
                size 0.02 0.02 0.02
              }
            }
          ]
          name "ps7"
        }
        DistanceSensor {
          translation -0.129432 -0.0799884 0
          rotation 0 0 1 -2.3869953071795864
          children [
            Shape {
              appearance PBRAppearance {
              }
              geometry Box {
                size 0.02 0.02 0.02
              }
            }
          ]
          name "ps8"
          lookupTable [
            0 0 0
            0 0 0
          ]
        }
        DistanceSensor {
          translation -0.119933 0.0969376 0
          rotation 0 0 -1 -2.587185307179586
          children [
            Shape {
              appearance PBRAppearance {
              }
              geometry Box {
                size 0.02 0.02 0.02
              }
            }
          ]
          name "ps9"
        }
        DistanceSensor {
          translation -0.0636266 0.138524 0
          rotation 0 0 -1 -2.0635853071795864
          children [
            Shape {
              appearance PBRAppearance {
              }
              geometry Box {
                size 0.02 0.02 0.02
              }
            }
          ]
          name "ps10"
        }
        DistanceSensor {
          translation 0.0658694 0.130151 0
          rotation 0 0 -1 -1.0163853071795863
          children [
            Shape {
              appearance PBRAppearance {
              }
              geometry Box {
                size 0.02 0.02 0.02
              }
            }
          ]
          name "ps11"
        }
        DistanceSensor {
          translation 0.165431 0.219068 0.5
          rotation 0 0 1 0.25
          children [
            Shape {
              appearance PBRAppearance {
              }
              geometry Box {
                size 0.02 0.02 0.02
              }
            }
          ]
          name "ps12"
          lookupTable [
            0 0 0
            5 5 0
            10 10 0
            15 15 0
            20 20 0
          ]
        }
        Shape {
          appearance Plastic {
            colorOverride 0.666667 0.333333 0.498039
          }
          geometry Cylinder {
            height 0.1
            radius 0.15
          }
        }
      ]
      name "sensor holder"
    }
    DEF RFWheel HingeJoint {
      jointParameters HingeJointParameters {
        position 60120.178400039295
        axis 0 1 0
        anchor -0.2 -0.269 0
      }
      device [
        PositionSensor {
        }
        RotationalMotor {
          name "rfmotor"
        }
      ]
      endPoint Solid {
        translation -0.20000334531399164 -0.269 6.422427870524917e-06
        rotation 0.17051685410491632 0.6970283979808238 -0.6964735564789585 2.8035437517325335
        children [
          DEF Wheel Shape {
            appearance GenericTireAppearance {
            }
            geometry Cylinder {
              height 0.03
              radius 0.07
            }
          }
        ]
        boundingObject USE Wheel
      }
    }
    DEF RBWheel HingeJoint {
      jointParameters HingeJointParameters {
        position 60138.18864003641
        axis 0 1 0
        anchor 0.2 -0.269 0
      }
      device [
        PositionSensor {
        }
        RotationalMotor {
          name "rbmotor"
        }
      ]
      endPoint Solid {
        translation 0.19999298594055567 -0.269 1.8004653748783847e-06
        rotation -0.48077595244342586 -0.6202687896847805 0.6197750495906513 4.038515626710614
        children [
          DEF Wheel Shape {
            appearance GenericTireAppearance {
            }
            geometry Cylinder {
              height 0.03
              radius 0.07
            }
          }
        ]
        name "solid(1)"
        boundingObject USE Wheel
      }
    }
    DEF LFWheel HingeJoint {
      jointParameters HingeJointParameters {
        position 54786.11968001111
        axis 0 1 0
        anchor -0.2 0.269 0
      }
      device [
        PositionSensor {
        }
        RotationalMotor {
          name "lfmotor"
        }
      ]
      endPoint Solid {
        translation -0.20000082809848185 0.269 7.193952902346833e-06
        rotation -0.04051428220398841 -0.7068074746888129 0.7062448489451224 3.222641373046411
        children [
          DEF Wheel Shape {
            appearance GenericTireAppearance {
            }
            geometry Cylinder {
              height 0.03
              radius 0.07
            }
          }
        ]
        name "solid(2)"
        boundingObject USE Wheel
      }
    }
    DEF LBWheel HingeJoint {
      jointParameters HingeJointParameters {
        position 54786.1796800111
        axis 0 1 0
        anchor 0.2 0.269 0
      }
      device [
        PositionSensor {
        }
        RotationalMotor {
          name "lbmotor"
        }
      ]
      endPoint Solid {
        translation 0.19999960476988668 0.269 7.2306637740960274e-06
        rotation -0.019299628633600623 -0.7072565144390776 0.7066935312553042 3.180217857909225
        children [
          DEF Wheel Shape {
            appearance GenericTireAppearance {
            }
            geometry Cylinder {
              height 0.03
              radius 0.07
            }
          }
        ]
        name "solid(3)"
        boundingObject USE Wheel
      }
    }
    DEF Base Shape {
      appearance Plastic {
        colorOverride 0.388235 0 0
      }
      geometry Box {
        size 0.5 0.5 0.1
      }
    }
    Solid {
      translation -0.24 0 0.429999
      rotation 0 1 0 -1.5707996938995747
      children [
        Shape {
          appearance PBRAppearance {
          }
          geometry Box {
            size 0.8 0.5 0.03
          }
        }
      ]
      name "chairback"
    }
    Solid {
      translation -0.02 0 0.41
      children [
        Shape {
          appearance Plastic {
            colorOverride 0 0.333333 1
          }
          geometry Box {
            size 0.4 0.5 0.03
          }
        }
      ]
      name "chairbottom"
    }
    Solid {
      translation -0.21 0 0.6
      rotation 0 1 0 -1.5708003061004252
      children [
        Shape {
          appearance Plastic {
            colorOverride 0 0.333333 1
          }
          geometry Box {
            size 0.4 0.5 0.03
          }
        }
      ]
      name "chairback"
    }
    Solid {
      translation -0.04 0.22 0.6
      rotation 0 1 0 0
      children [
        Shape {
          appearance Plastic {
            colorOverride 0 0.333333 1
          }
          geometry Box {
            size 0.4 0.05 0.03
          }
        }
      ]
      name "chairsidearm1"
    }
    Solid {
      translation -0.04 -0.23 0.6
      rotation 0 1 0 0
      children [
        Shape {
          appearance Plastic {
            colorOverride 0 0.333333 1
          }
          geometry Box {
            size 0.4 0.05 0.03
          }
        }
      ]
      name "chairsidearm2"
    }
  ]
  name "robot(1)"
  controller "my_controller"
  selfCollision TRUE
}
PalmTree {
  translation -10.27 3.86 0
}
Toilet {
  translation 4.31 -3.89 0
  rotation 0 0 1 3.14159
}
Door {
  hidden translation_5 -0.5046038703161334 -0.23721969871299864 4.440892098500626e-16
  hidden rotation_5 0 0 1 0.5740851237077895
  translation -4.87 -0.020004 0
  rotation 0 0 1 3.14159
  name "door1"
  size 0.2 2 2.5
  position -1.5677411095573606
}
Sofa {
  translation -2.94 -4.11 0
  rotation 0 0 1 1.5708
}
Sofa {
  translation -4.41 -2.53 0
  name "sofa(1)"
}
Bed {
  translation -3.07 3.97 -0.29
  rotation 0 0 1 -1.5707953071795862
}
DEF Wall_1 Wall {
  translation 0 5 0
  size 10 0.1 2.5
  appearance Roughcast {
    colorOverride 0.647059 0.647059 0.647059
    textureTransform TextureTransform {
      scale 2.4 1
    }
  }
}
Shape {
  geometry Box {
    size 0.1 0.1 0.1
  }
}
DEF Wall_2 Wall {
  translation 0 -5 0
  name "wall(1)"
  size 10 0.1 2.5
  appearance Roughcast {
    colorOverride 0.647059 0.647059 0.647059
    textureTransform TextureTransform {
      scale 2.4 1
    }
  }
}
DEF Wall_3 Wall {
  translation 5 0 0
  rotation 0 0 1 1.57
  name "wall(2)"
  size 10 0.1 2.5
  appearance Roughcast {
    colorOverride 0.647059 0.647059 0.647059
    textureTransform TextureTransform {
      scale 2.4 1
    }
  }
}
DEF Wall_4 Wall {
  translation -5 -3 0
  rotation 0 0 1 1.57
  name "wall(3)"
  size 4 0.1 2.5
  appearance Roughcast {
    colorOverride 0.647059 0.647059 0.647059
    textureTransform TextureTransform {
      scale 2.4 1
    }
  }
}
DEF Wall_4 Wall {
  translation 0.76 -2.99976 0
  rotation 0 0 1 1.57
  name "wall(8)"
  size 4 0.1 2.5
  appearance Roughcast {
    colorOverride 0.647059 0.647059 0.647059
    textureTransform TextureTransform {
      scale 2.4 1
    }
  }
}
DEF Wall_4 Wall {
  translation 1.22483 3.02985 0
  rotation 0 0 1 1.57
  name "wall(5)"
  size 4 0.1 2.5
  appearance Roughcast {
    colorOverride 0.647059 0.647059 0.647059
    textureTransform TextureTransform {
      scale 2.4 1
    }
  }
}
DEF Wall_4 Wall {
  translation 3.68072 -2.39 0.0713361
  rotation 0 1 0 -0.000795307179585869
  name "wall(9)"
  size 2.5 0.1 2
  appearance Roughcast {
    colorOverride 0.647059 0.647059 0.647059
    textureTransform TextureTransform {
      scale 2.4 1
    }
  }
}
DEF Wall_4 Wall {
  translation -5.00123 -3.53 0
  rotation 0 0 1 1.57
  name "wall(7)"
  size 3 0.1 1
  appearance Roughcast {
    colorOverride 0.647059 0.647059 0.647059
    textureTransform TextureTransform {
      scale 2.4 1
    }
  }
}
DEF Wall_5 Wall {
  translation -5 3 0
  rotation 0 0 1 1.57
  name "wall(4)"
  size 4 0.1 2.5
  appearance Roughcast {
    colorOverride 0.647059 0.647059 0.647059
    textureTransform TextureTransform {
      scale 2.4 1
    }
  }
}
DEF Wall_6 Wall {
  translation -3.02957 0.806903 -0.0650753
  rotation 1 0 0 -0.1308996938995747
  name "wall(6)"
  size 4 0.1 2.5
  appearance Roughcast {
    colorOverride 0.647059 0.647059 0.647059
    textureTransform TextureTransform {
      scale 2.4 1
    }
  }
}
Tree {
  translation -7 -4 0
}
PicketFence {
  translation -14.93 4.95 0
  rotation 0 0 1 1.5707996938995747
}
PicketFence {
  translation -14.93 -4.8 0
  rotation 0 0 1 1.5707996938995747
  name "picket fence(11)"
}
PicketFence {
  translation -13.23 -4.8 0
  rotation 0 0 1 1.5707996938995747
  name "picket fence(12)"
}
PicketFence {
  translation -11.54 -4.8 0
  rotation 0 0 1 1.5707996938995747
  name "picket fence(13)"
}
PicketFence {
  translation -9.88 -4.8 0
  rotation 0 0 1 1.5707996938995747
  name "picket fence(14)"
}
PicketFence {
  translation -8.27 -4.8 0
  rotation 0 0 1 1.5707996938995747
  name "picket fence(15)"
}
PicketFence {
  translation -6.59 -4.8 0
  rotation 0 0 1 1.5707996938995747
  name "picket fence(16)"
}
PicketFence {
  translation -13.33 4.95 0
  rotation 0 0 1 1.5707996938995747
  name "picket fence(6)"
}
PicketFence {
  translation -11.63 4.95 0
  rotation 0 0 1 1.5707996938995747
  name "picket fence(7)"
}
PicketFence {
  translation -9.91 4.95 0
  rotation 0 0 1 1.5707996938995747
  name "picket fence(8)"
}
PicketFence {
  translation -8.18 4.95 0
  rotation 0 0 1 1.5707996938995747
  name "picket fence(9)"
}
PicketFence {
  translation -6.75 4.95 0
  rotation 0 0 1 1.5707996938995747
  name "picket fence(10)"
}
PicketFence {
  translation -14.93 3.19 0
  name "picket fence(1)"
}
PicketFence {
  translation -14.93 4.92 0
  name "picket fence(5)"
}
PicketFence {
  translation -14.93 -0.19 0
  rotation 0 0 1 3.141592653589793
  name "picket fence(4)"
}
PicketFence {
  translation -14.93 -3.19 0
  name "picket fence(2)"
}
PicketFence {
  translation -14.93 -1.43 0
  name "picket fence(3)"
}
Floor {
  translation -10 0 0
  name "floor(1)"
  appearance Parquetry {
  }
}
TableWithUmbrella {
  translation -6.73 3.71 0
}
